Workbook
Name Slicer_Priority: #N/A
Name Slicer_SLA_Result: #N/A
Name Slicer_Status: #N/A
Name Slicer_SubCategory: #N/A
Name Slicer_TicketType: #N/A
Name Timeline_BookingDate: #N/A

Sheet README
A1: Purpose | B1: Portfolio-ready synthetic ITSM dataset for Excel Incident Analysis.
A2: Volume | B2: 3,000 rows: 1,000 INM + 1,000 PRM + 1,000 SRM.
A3: Date Range | B3: 2024-01-01 to 2025-12-31.
A4: Statuses | B4: Assigned, Noticed, In Process, Answered, Closed.
A5: SLA Logic | B5: Assigned/Noticed/In Process = Pending; Answered/Closed = Met or Breached based on resolution time.
A6: Recommended Analysis | B6: Ticket volume, SLA compliance, priority, backlog, resolution time, team workload, category and monthly trends.

Sheet All_Tickets
A1: TicketID | B1: TicketType | C1: BookingDate | D1: Priority | E1: Category | F1: SubCategory | G1: ShortDescription | H1: Status | I1: AssignedTeam | J1: Assignee | K1: SLATargetHours | L1: FirstResponseHours | M1: ResolutionHours | N1: ResolutionDate | O1: ResolutionSLA | P1: AgingHours | Q1: CustomerImpact | R1: Region | S1: Channel | T1: RootCause | U1: Reopened | V1: Escalated | W1: SLA Result | X1: Year | Y1: Month | Z1: Month-Year | AA1: Resolution Bucket | AB1: SLA Variance
A2: SRM-0425 | B2: SRM | C2: 45292.101 | D2: P4 | E2: Access Request | F2: Security | G2: SRM ticket requiring operational handling | H2: In Process | I2: Service Desk | J2: Suresh | K2: 48 | L2: 2.24 | O2: Pending | P2: 17517.57 | Q2: High | R2: US | S2: Service Desk | T2: Certificate Expiry | U2: No | V2: No | W2: Pending | X2: =YEAR(Table1[[#This Row],[BookingDate]]) -> 2024 | Y2: =TEXT(Table1[[#This Row],[BookingDate]],"mmm") -> Jan | Z2: =TEXT(Table1[[#This Row],[BookingDate]],"mmm-yyy") -> Jan-2024 | AA2: =IF(Table1[[#This Row],[ResolutionHours]]="","Pending",IF(Table1[[#This Row],[ResolutionHours]]<=4,"0-4 Hours",IF(Table1[[#This Row],[ResolutionHours]]<=8,"5-8 Hours",IF(Table1[[#This Row],[ResolutionHours]]<=24,"9-24 Hours",IF(Table1[[#This Row],[ResolutionHours]]<=48,"25-48 Hours","48+ Hours"))))) -> Pending | AB2: =IF(Table1[[#This Row],[ResolutionHours]]="","",Table1[[#This Row],[ResolutionHours]]-Table1[[#This Row],[SLATargetHours]])
A3: SRM-0365 | B3: SRM | C3: 45292.317 | D3: P5 | E3: Configuration Change | F3: Middleware | G3: SRM ticket requiring operational handling | H3: Closed | I3: Service Desk | J3: Priya | K3: 72 | L3: 16.8 | M3: 68.84 | N3: 45295.185 | O3: Met | P3: 68.84 | Q3: Medium | R3: APAC | S3: Service Desk | T3: Network Issue | U3: No | V3: No | W3: Met | X3: =YEAR(Table1[[#This Row],[BookingDate]]) -> 2024 | Y3: =TEXT(Table1[[#This Row],[BookingDate]],"mmm") -> Jan | Z3: =TEXT(Table1[[#This Row],[BookingDate]],"mmm-yyy") -> Jan-2024 | AA3: =IF(Table1[[#This Row],[ResolutionHours]]="","Pending",IF(Table1[[#This Row],[ResolutionHours]]<=4,"0-4 Hours",IF(Table1[[#This Row],[ResolutionHours]]<=8,"5-8 Hours",IF(Table1[[#This Row],[ResolutionHours]]<=24,"9-24 Hours",IF(Table1[[#This Row],[ResolutionHours]]<=48,"25-48 Hours","48+ Hours"))))) -> 48+ Hours | AB3: =IF(Table1[[#This Row],[ResolutionHours]]="","",Table1[[#This Row],[ResolutionHours]]-Table1[[#This Row],[SLATargetHours]]) -> -3.16
A4: SRM-0496 | B4: SRM | C4: 45292.35 | D4: P3 | E4: Access Request | F4: Middleware | G4: SRM ticket requiring operational handling | H4: In Process | I4: Service Desk | J4: Vikram | K4: 24 | L4: 2.36 | O4: Pending | P4: 17511.6 | Q4: Low | R4: APAC | S4: Monitoring Alert | T4: Unknown | U4: No | V4: No | W4: Pending | X4: =YEAR(Table1[[#This Row],[BookingDate]]) -> 2024 | Y4: =TEXT(Table1[[#This Row],[BookingDate]],"mmm") -> Jan | Z4: =TEXT(Table1[[#This Row],[BookingDate]],"mmm-yyy") -> Jan-2024 | AA4: =IF(Table1[[#This Row],[ResolutionHours]]="","Pending",IF(Table1[[#This Row],[ResolutionHours]]<=4,"0-4 Hours",IF(Table1[[#This Row],[ResolutionHours]]<=8,"5-8 Hours",IF(Table1[[#This Row],[ResolutionHours]]<=24,"9-24 Hours",IF(Table1[[#This Row],[ResolutionHours]]<=48,"25-48 Hours","48+ Hours"))))) -> Pending | AB4: =IF(Table1[[#This Row],[ResolutionHours]]="","",Table1[[#This Row],[ResolutionHours]]-Table1[[#This Row],[SLATargetHours]])
A5: SRM-0400 | B5: SRM | C5: 45292.716 | D5: P3 | E5: Data Request | F5: Access | G5: SRM ticket requiring operational handling | H5: Noticed | I5: Middleware Team | J5: Sneha | K5: 24 | L5: 0.47 | O5: Pending | P5: 17502.81 | Q5: Low | R5: APAC | S5: Portal | T5: Access Issue | U5: No | V5: Yes | W5: Pending | X5: =YEAR(Table1[[#This Row],[BookingDate]]) -> 2024 | Y5: =TEXT(Table1[[#This Row],[BookingDate]],"mmm") -> Jan | Z5: =TEXT(Table1[[#This Row],[BookingDate]],"mmm-yyy") -> Jan-2024 | AA5: =IF(Table1[[#This Row],[ResolutionHours]]="","Pending",IF(Table1[[#This Row],[ResolutionHours]]<=4,"0-4 Hours",IF(Table1[[#This Row],[ResolutionHours]]<=8,"5-8 Hours",IF(Table1[[#This Row],[ResolutionHours]]<=24,"9-24 Hours",IF(Table1[[#This Row],[ResolutionHours]]<=48,"25-48 Hours","48+ Hours"))))) -> Pending | AB5: =IF(Table1[[#This Row],[ResolutionHours]]="","",Table1[[#This Row],[ResolutionHours]]-Table1[[#This Row],[SLATargetHours]])
A6: PRM-0763 | B6: PRM | C6: 45293.085 | D6: P4 | E6: Recurring Application Issue | F6: Access | G6: PRM ticket requiring operational handling | H6: In Process | I6: Database Team | J6: Meera | K6: 48 | L6: 0.54 | O6: Pending | P6: 17493.96 | Q6: High | R6: India | S6: Service Desk | T6: Certificate Expiry | U6: No | V6: No | W6: Pending | X6: =YEAR(Table1[[#This Row],[BookingDate]]) -> 2024 | Y6: =TEXT(Table1[[#This Row],[BookingDate]],"mmm") -> Jan | Z6: =TEXT(Table1[[#This Row],[BookingDate]],"mmm-yyy") -> Jan-2024 | AA6: =IF(Table1[[#This Row],[ResolutionHours]]="","Pending",IF(Table1[[#This Row],[ResolutionHours]]<=4,"0-4 Hours",IF(Table1[[#This Row],[ResolutionHours]]<=8,"5-8 Hours",IF(Table1[[#This Row],[ResolutionHours]]<=24,"9-24 Hours",IF(Table1[[#This Row],[ResolutionHours]]<=48,"25-48 Hours","48+ Hours"))))) -> Pending | AB6: =IF(Table1[[#This Row],[ResolutionHours]]="","",Table1[[#This Row],[ResolutionHours]]-Table1[[#This Row],[SLATargetHours]])
A7: PRM-0241 | B7: PRM | C7: 45293.465 | D7: P3 | E7: Process Gap | F7: Middleware | G7: PRM ticket requiring operational handling | H7: In Process | I7: App Support | J7: Anil | K7: 24 | L7: 3.22 | O7: Pending | P7: 17484.84 | Q7: Low | R7: India | S7: Service Desk | T7: Certificate Expiry | U7: No | V7: No | W7: Pending | X7: =YEAR(Table1[[#This Row],[BookingDate]]) -> 2024 | Y7: =TEXT(Table1[[#This Row],[BookingDate]],"mmm") -> Jan | Z7: =TEXT(Table1[[#This Row],[BookingDate]],"mmm-yyy") -> Jan-2024 | AA7: =IF(Table1[[#This Row],[ResolutionHours]]="","Pending",IF(Table1[[#This Row],[ResolutionHours]]<=4,"0-4 Hours",IF(Table1[[#This Row],[ResolutionHours]]<=8,"5-8 Hours",IF(Table1[[#This Row],[ResolutionHours]]<=24,"9-24 Hours",IF(Table1[[#This Row],[ResolutionHours]]<=48,"25-48 Hours","48+ Hours"))))) -> Pending | AB7: =IF(Table1[[#This Row],[ResolutionHours]]="","",Table1[[#This Row],[ResolutionHours]]-Table1[[#This Row],[SLATargetHours]])
A8: SRM-0428 | B8: SRM | C8: 45293.537 | D8: P5 | E8: New User Setup | F8: Security | G8: SRM ticket requiring operational handling | H8: Noticed | I8: Service Desk | J8: Suresh | K8: 72 | L8: 12.63 | O8: Pending | P8: 17483.12 | Q8: Medium | R8: UK | S8: Portal | T8: Unknown | U8: No | V8: No | W8: Pending | X8: =YEAR(Table1[[#This Row],[BookingDate]]) -> 2024 | Y8: =TEXT(Table1[[#This Row],[BookingDate]],"mmm") -> Jan | Z8: =TEXT(Table1[[#This Row],[BookingDate]],"mmm-yyy") -> Jan-2024 | AA8: =IF(Table1[[#This Row],[ResolutionHours]]="","Pending",IF(Table1[[#This Row],[ResolutionHours]]<=4,"0-4 Hours",IF(Table1[[#This Row],[ResolutionHours]]<=8,"5-8 Hours",IF(Table1[[#This Row],[ResolutionHours]]<=24,"9-24 Hours",IF(Table1[[#This Row],[ResolutionHours]]<=48,"25-48 Hours","48+ Hours"))))) -> Pending | AB8: =IF(Table1[[#This Row],[ResolutionHours]]="","",Table1[[#This Row],[ResolutionHours]]-Table1[[#This Row],[SLATargetHours]])
A9: PRM-0518 | B9: PRM | C9: 45293.922 | D9: P5 | E9: Integration Root Cause | F9: Security | G9: PRM ticket requiring operational handling | H9: Noticed | I9: App Support | J9: Neha | K9: 72 | L9: 5.36 | O9: Pending | P9: 17473.87 | Q9: Low | R9: US | S9: Service Desk | T9: Infrastructure Failure | U9: No | V9: No | W9: Pending | X9: =YEAR(Table1[[#This Row],[BookingDate]]) -> 2024 | Y9: =TEXT(Table1[[#This Row],[BookingDate]],"mmm") -> Jan | Z9: =TEXT(Table1[[#This Row],[BookingDate]],"mmm-yyy") -> Jan-2024 | AA9: =IF(Table1[[#This Row],[ResolutionHours]]="","Pending",IF(Table1[[#This Row],[ResolutionHours]]<=4,"0-4 Hours",IF(Table1[[#This Row],[ResolutionHours]]<=8,"5-8 Hours",IF(Table1[[#This Row],[ResolutionHours]]<=24,"9-24 Hours",IF(Table1[[#This Row],[ResolutionHours]]<=48,"25-48 Hours","48+ Hours"))))) -> Pending | AB9: =IF(Table1[[#This Row],[ResolutionHours]]="","",Table1[[#This Row],[ResolutionHours]]-Table1[[#This Row],[SLATargetHours]])
A10: SRM-0677 | B10: SRM | C10: 45294.275 | D10: P4 | E10: Data Request | F10: Application | G10: SRM ticket requiring operational handling | H10: In Process | I10: Middleware Team | J10: Ravi | K10: 48 | L10: 2.54 | O10: Pending | P10: 17465.4 | Q10: Low | R10: APAC | S10: Service Desk | T10: Access Issue | U10: No | V10: No | W10: Pending | X10: =YEAR(Table1[[#This Row],[BookingDate]]) -> 2024 | Y10: =TEXT(Table1[[#This Row],[BookingDate]],"mmm") -> Jan | Z10: =TEXT(Table1[[#This Row],[BookingDate]],"mmm-yyy") -> Jan-2024 | AA10: =IF(Table1[[#This Row],[ResolutionHours]]="","Pending",IF(Table1[[#This Row],[ResolutionHours]]<=4,"0-4 Hours",IF(Table1[[#This Row],[ResolutionHours]]<=8,"5-8 Hours",IF(Table1[[#This Row],[ResolutionHours]]<=24,"9-24 Hours",IF(Table1[[#This Row],[ResolutionHours]]<=48,"25-48 Hours","48+ Hours"))))) -> Pending | AB10: =IF(Table1[[#This Row],[ResolutionHours]]="","",Table1[[#This Row],[ResolutionHours]]-Table1[[#This Row],[SLATargetHours]])
A11: SRM-0040 | B11: SRM | C11: 45294.58 | D11: P4 | E11: Configuration Change | F11: Access | G11: SRM ticket requiring operational handling | H11: Closed | I11: App Support | J11: Anil | K11: 48 | L11: 0.96 | M11: 29.6 | N11: 45295.814 | O11: Met | P11: 29.6 | Q11: Low | R11: UK | S11: Portal | T11: Third-Party Dependency | U11: No | V11: No | W11: Met | X11: =YEAR(Table1[[#This Row],[BookingDate]]) -> 2024 | Y11: =TEXT(Table1[[#This Row],[BookingDate]],"mmm") -> Jan | Z11: =TEXT(Table1[[#This Row],[BookingDate]],"mmm-yyy") -> Jan-2024 | AA11: =IF(Table1[[#This Row],[ResolutionHours]]="","Pending",IF(Table1[[#This Row],[ResolutionHours]]<=4,"0-4 Hours",IF(Table1[[#This Row],[ResolutionHours]]<=8,"5-8 Hours",IF(Table1[[#This Row],[ResolutionHours]]<=24,"9-24 Hours",IF(Table1[[#This Row],[ResolutionHours]]<=48,"25-48 Hours","48+ Hours"))))) -> 25-48 Hours | AB11: =IF(Table1[[#This Row],[ResolutionHours]]="","",Table1[[#This Row],[ResolutionHours]]-Table1[[#This Row],[SLATargetHours]]) -> -18.4
A12: SRM-0609 | B12: SRM | C12: 45294.795 | D12: P5 | E12: Configuration Change | F12: Database | G12: SRM ticket requiring operational handling | H12: In Process | I12: Security Team | J12: Arjun | K12: 72 | L12: 6.72 | O12: Pending | P12: 17452.93 | Q12: Low | R12: APAC | S12: Monitoring Alert | T12: Network Issue | U12: No | V12: No | W12: Pending | X12: =YEAR(Table1[[#This Row],[BookingDate]]) -> 2024 | Y12: =TEXT(Table1[[#This Row],[BookingDate]],"mmm") -> Jan | Z12: =TEXT(Table1[[#This Row],[BookingDate]],"mmm-yyy") -> Jan-2024 | AA12: =IF(Table1[[#This Row],[ResolutionHours]]="","Pending",IF(Table1[[#This Row],[ResolutionHours]]<=4,"0-4 Hours",IF(Table1[[#This Row],[ResolutionHours]]<=8,"5-8 Hours",IF(Table1[[#This Row],[ResolutionHours]]<=24,"9-24 Hours",IF(Table1[[#This Row],[ResolutionHours]]<=48,"25-48 Hours","48+ Hours"))))) -> Pending | AB12: =IF(Table1[[#This Row],[ResolutionHours]]="","",Table1[[#This Row],[ResolutionHours]]-Table1[[#This Row],[SLATargetHours]])
A13: INM-0901 | B13: INM | C13: 45295.201 | D13: P1 | E13: Certificate/TLS | F13: Middleware | G13: INM ticket requiring operational handling | H13: In Process | I13: Infrastructure Team | J13: Suresh | K13: 4 | L13: 0.24 | O13: Pending | P13: 17443.17 | Q13: Critical | R13: UK | S13: Monitoring Alert | T13: Application Defect | U13: No | V13: Yes | W13: Pending | X13: =YEAR(Table1[[#This Row],[BookingDate]]) -> 2024 | Y13: =TEXT(Table1[[#This Row],[BookingDate]],"mmm") -> Jan | Z13: =TEXT(Table1[[#This Row],[BookingDate]],"mmm-yyy") -> Jan-2024 | AA13: =IF(Table1[[#This Row],[ResolutionHours]]="","Pending",IF(Table1[[#This Row],[ResolutionHours]]<=4,"0-4 Hours",IF(Table1[[#This Row],[ResolutionHours]]<=8,"5-8 Hours",IF(Table1[[#This Row],[ResolutionHours]]<=24,"9-24 Hours",IF(Table1[[#This Row],[ResolutionHours]]<=48,"25-48 Hours","48+ Hours"))))) -> Pending | AB13: =IF(Table1[[#This Row],[ResolutionHours]]="","",Table1[[#This Row],[ResolutionHours]]-Table1[[#This Row],[SLATargetHours]])
A14: PRM-1000 | B14: PRM | C14: 45295.294 | D14: P4 | E14: Security Vulnerability | F14: Reporting | G14: PRM ticket requiring operational handling | H14: Closed | I14: Security Team | J14: Neha | K14: 48 | L14: 3.73 | M14: 41.06 | N14: 45297.005 | O14: Met | P14: 41.06 | Q14: High | R14: UK | S14: Phone | T14: Application Defect | U14: No | V14: No | W14: Met | X14: =YEAR(Table1[[#This Row],[BookingDate]]) -> 2024 | Y14: =TEXT(Table1[[#This Row],[BookingDate]],"mmm") -> Jan | Z14: =TEXT(Table1[[#This Row],[BookingDate]],"mmm-yyy") -> Jan-2024 | AA14: =IF(Table1[[#This Row],[ResolutionHours]]="","Pending",IF(Table1[[#This Row],[ResolutionHours]]<=4,"0-4 Hours",IF(Table1[[#This Row],[ResolutionHours]]<=8,"5-8 Hours",IF(Table1[[#This Row],[ResolutionHours]]<=24,"9-24 Hours",IF(Table1[[#This Row],[ResolutionHours]]<=48,"25-48 Hours","48+ Hours"))))) -> 25-48 Hours | AB14: =IF(Table1[[#This Row],[ResolutionHours]]="","",Table1[[#This Row],[ResolutionHours]]-Table1[[#This Row],[SLATargetHours]]) -> -6.94
A15: INM-0773 | B15: INM | C15: 45295.575 | D15: P1 | E15: Login/Access | F15: Application | G15: INM ticket requiring operational handling | H15: In Process | I15: Middleware Team | J15: Arjun | K15: 4 | L15: 0.4 | O15: Pending | P15: 17434.2 | Q15: Critical | R15: Europe | S15: Monitoring Alert | T15: Certificate Expiry | U15: No | V15: No | W15: Pending | X15: =YEAR(Table1[[#This Row],[BookingDate]]) -> 2024 | Y15: =TEXT(Table1[[#This Row],[BookingDate]],"mmm") -> Jan | Z15: =TEXT(Table1[[#This Row],[BookingDate]],"mmm-yyy") -> Jan-2024 | AA15: =IF(Table1[[#This Row],[ResolutionHours]]="","Pending",IF(Table1[[#This Row],[ResolutionHours]]<=4,"0-4 Hours",IF(Table1[[#This Row],[ResolutionHours]]<=8,"5-8 Hours",IF(Table1[[#This Row],[ResolutionHours]]<=24,"9-24 Hours",IF(Table1[[#This Row],[ResolutionHours]]<=48,"25-48 Hours","48+ Hours"))))) -> Pending | AB15: =IF(Table1[[#This Row],[ResolutionHours]]="","",Table1[[#This Row],[ResolutionHours]]-Table1[[#This Row],[SLATargetHours]])
A16: SRM-0444 | B16: SRM | C16: 45295.716 | D16: P2 | E16: Account Request | F16: Application | G16: SRM ticket requiring operational handling | H16: Closed | I16: Database Team | J16: Anil | K16: 8 | L16: 1.01 | M16: 7.08 | N16: 45296.011 | O16: Met | P16: 7.08 | Q16: High | R16: US | S16: Email | T16: Configuration Error | U16: No | V16: No | W16: Met | X16: =YEAR(Table1[[#This Row],[BookingDate]]) -> 2024 | Y16: =TEXT(Table1[[#This Row],[BookingDate]],"mmm") -> Jan | Z16: =TEXT(Table1[[#This Row],[BookingDate]],"mmm-yyy") -> Jan-2024 | AA16: =IF(Table1[[#This Row],[ResolutionHours]]="","Pending",IF(Table1[[#This Row],[ResolutionHours]]<=4,"0-4 Hours",IF(Table1[[#This Row],[ResolutionHours]]<=8,"5-8 Hours",IF(Table1[[#This Row],[ResolutionHours]]<=24,"9-24 Hours",IF(Table1[[#This Row],[ResolutionHours]]<=48,"25-48 Hours","48+ Hours"))))) -> 5-8 Hours | AB16: =IF(Table1[[#This Row],[ResolutionHours]]="","",Table1[[#This Row],[ResolutionHours]]-Table1[[#This Row],[SLATargetHours]]) -> -0.92
A17: INM-0381 | B17: INM | C17: 45295.879 | D17: P3 | E17: Certificate/TLS | F17: Application | G17: INM ticket requiring operational handling | H17: Closed | I17: Service Desk | J17: Kavya | K17: 24 | L17: 0.61 | M17: 12.38 | N17: 45296.395 | O17: Met | P17: 12.38 | Q17: Low | R17: US | S17: Monitoring Alert | T17: Certificate Expiry | U17: No | V17: No | W17: Met | X17: =YEAR(Table1[[#This Row],[BookingDate]]) -> 2024 | Y17: =TEXT(Table1[[#This Row],[BookingDate]],"mmm") -> Jan | Z17: =TEXT(Table1[[#This Row],[BookingDate]],"mmm-yyy") -> Jan-2024 | AA17: =IF(Table1[[#This Row],[ResolutionHours]]="","Pending",IF(Table1[[#This Row],[ResolutionHours]]<=4,"0-4 Hours",IF(Table1[[#This Row],[ResolutionHours]]<=8,"5-8 Hours",IF(Table1[[#This Row],[ResolutionHours]]<=24,"9-24 Hours",IF(Table1[[#This Row],[ResolutionHours]]<=48,"25-48 Hours","48+ Hours"))))) -> 9-24 Hours | AB17: =IF(Table1[[#This Row],[ResolutionHours]]="","",Table1[[#This Row],[ResolutionHours]]-Table1[[#This Row],[SLATargetHours]]) -> -11.62
A18: INM-0846 | B18: INM | C18: 45295.969 | D18: P2 | E18: Login/Access | F18: Middleware | G18: INM ticket requiring operational handling | H18: Closed | I18: Service Desk | J18: Ravi | K18: 8 | L18: 0.68 | M18: 2.57 | N18: 45296.076 | O18: Met | P18: 2.57 | Q18: High | R18: Europe | S18: Portal | T18: Access Issue | U18: No | V18: No | W18: Met | X18: =YEAR(Table1[[#This Row],[BookingDate]]) -> 2024 | Y18: =TEXT(Table1[[#This Row],[BookingDate]],"mmm") -> Jan | Z18: =TEXT(Table1[[#This Row],[BookingDate]],"mmm-yyy") -> Jan-2024 | AA18: =IF(Table1[[#This Row],[ResolutionHours]]="","Pending",IF(Table1[[#This Row],[ResolutionHours]]<=4,"0-4 Hours",IF(Table1[[#This Row],[ResolutionHours]]<=8,"5-8 Hours",IF(Table1[[#This Row],[ResolutionHours]]<=24,"9-24 Hours",IF(Table1[[#This Row],[ResolutionHours]]<=48,"25-48 Hours","48+ Hours"))))) -> 0-4 Hours | AB18: =IF(Table1[[#This Row],[ResolutionHours]]="","",Table1[[#This Row],[ResolutionHours]]-Table1[[#This Row],[SLATargetHours]]) -> -5.43
A19: INM-0845 | B19: INM | C19: 45296.001 | D19: P4 | E19: Certificate/TLS | F19: Reporting | G19: INM ticket requiring operational handling | H19: Closed | I19: Security Team | J19: Suresh | K19: 48 | L19: 7.46 | M19: 7.98 | N19: 45296.334 | O19: Met | P19: 7.98 | Q19: Medium | R19: UK | S19: Service Desk | T19: Application Defect | U19: No | V19: No | W19: Met | X19: =YEAR(Table1[[#This Row],[BookingDate]]) -> 2024 | Y19: =TEXT(Table1[[#This Row],[BookingDate]],"mmm") -> Jan | Z19: =TEXT(Table1[[#This Row],[BookingDate]],"mmm-yyy") -> Jan-2024 | AA19: =IF(Table1[[#This Row],[ResolutionHours]]="","Pending",IF(Table1[[#This Row],[ResolutionHours]]<=4,"0-4 Hours",IF(Table1[[#This Row],[ResolutionHours]]<=8,"5-8 Hours",IF(Table1[[#This Row],[ResolutionHours]]<=24,"9-24 Hours",IF(Table1[[#This Row],[ResolutionHours]]<=48,"25-48 Hours","48+ Hours"))))) -> 5-8 Hours | AB19: =IF(Table1[[#This Row],[ResolutionHours]]="","",Table1[[#This Row],[ResolutionHours]]-Table1[[#This Row],[SLATargetHours]]) -> -40.02
A20: PRM-0525 | B20: PRM | C20: 45296.019 | D20: P5 | E20: Security Vulnerability | F20: Database | G20: PRM ticket requiring operational handling | H20: Closed | I20: Service Desk | J20: Rohit | K20: 72 | L20: 6.5 | M20: 35.51 | N20: 45297.498 | O20: Met | P20: 35.51 | Q20: Medium | R20: UK | S20: Service Desk | T20: Third-Party Dependency | U20: No | V20: Yes | W20: Met | X20: =YEAR(Table1[[#This Row],[BookingDate]]) -> 2024 | Y20: =TEXT(Table1[[#This Row],[BookingDate]],"mmm") -> Jan | Z20: =TEXT(Table1[[#This Row],[BookingDate]],"mmm-yyy") -> Jan-2024 | AA20: =IF(Table1[[#This Row],[ResolutionHours]]="","Pending",IF(Table1[[#This Row],[ResolutionHours]]<=4,"0-4 Hours",IF(Table1[[#This Row],[ResolutionHours]]<=8,"5-8 Hours",IF(Table1[[#This Row],[ResolutionHours]]<=24,"9-24 Hours",IF(Table1[[#This Row],[ResolutionHours]]<=48,"25-48 Hours","48+ Hours"))))) -> 25-48 Hours | AB20: =IF(Table1[[#This Row],[ResolutionHours]]="","",Table1[[#This Row],[ResolutionHours]]-Table1[[#This Row],[SLATargetHours]]) -> -36.49
A21: PRM-0992 | B21: PRM | C21: 45296.576 | D21: P4 | E21: Database Root Cause | F21: Infrastructure | G21: PRM ticket requiring operational handling | H21: Closed | I21: App Support | J21: Asha | K21: 48 | L21: 1.86 | M21: 46.45 | N21: 45298.511 | O21: Met | P21: 46.45 | Q21: Medium | R21: US | S21: Phone | T21: Network Issue | U21: Yes | V21: No | W21: Met | X21: =YEAR(Table1[[#This Row],[BookingDate]]) -> 2024 | Y21: =TEXT(Table1[[#This Row],[BookingDate]],"mmm") -> Jan | Z21: =TEXT(Table1[[#This Row],[BookingDate]],"mmm-yyy") -> Jan-2024 | AA21: =IF(Table1[[#This Row],[ResolutionHours]]="","Pending",IF(Table1[[#This Row],[ResolutionHours]]<=4,"0-4 Hours",IF(Table1[[#This Row],[ResolutionHours]]<=8,"5-8 Hours",IF(Table1[[#This Row],[ResolutionHours]]<=24,"9-24 Hours",IF(Table1[[#This Row],[ResolutionHours]]<=48,"25-48 Hours","48+ Hours"))))) -> 25-48 Hours | AB21: =IF(Table1[[#This Row],[ResolutionHours]]="","",Table1[[#This Row],[ResolutionHours]]-Table1[[#This Row],[SLATargetHours]]) -> -1.55
A22: INM-0465 | B22: INM | C22: 45296.76 | D22: P1 | E22: Performance Issue | F22: Database | G22: INM ticket requiring operational handling | H22: Assigned | I22: Database Team | J22: Kavya | K22: 4 | L22: 0.13 | O22: Pending | P22: 17405.77 | Q22: Critical | R22: India | S22: Email | T22: Capacity Constraint | U22: No | V22: Yes | W22: Pending | X22: =YEAR(Table1[[#This Row],[BookingDate]]) -> 2024 | Y22: =TEXT(Table1[[#This Row],[BookingDate]],"mmm") -> Jan | Z22: =TEXT(Table1[[#This Row],[BookingDate]],"mmm-yyy") -> Jan-2024 | AA22: =IF(Table1[[#This Row],[ResolutionHours]]="","Pending",IF(Table1[[#This Row],[ResolutionHours]]<=4,"0-4 Hours",IF(Table1[[#This Row],[ResolutionHours]]<=8,"5-8 Hours",IF(Table1[[#This Row],[ResolutionHours]]<=24,"9-24 Hours",IF(Table1[[#This Row],[ResolutionHours]]<=48,"25-48 Hours","48+ Hours"))))) -> Pending | AB22: =IF(Table1[[#This Row],[ResolutionHours]]="","",Table1[[#This Row],[ResolutionHours]]-Table1[[#This Row],[SLATargetHours]])
A23: PRM-0139 | B23: PRM | C23: 45296.785 | D23: P1 | E23: Database Root Cause | F23: Application | G23: PRM ticket requiring operational handling | H23: Closed | I23: Service Desk | J23: Divya | K23: 4 | L23: 0.1 | M23: 3.6 | N23: 45296.935 | O23: Met | P23: 3.6 | Q23: Critical | R23: US | S23: Portal | T23: Application Defect | U23: No | V23: No | W23: Met | X23: =YEAR(Table1[[#This Row],[BookingDate]]) -> 2024 | Y23: =TEXT(Table1[[#This Row],[BookingDate]],"mmm") -> Jan | Z23: =TEXT(Table1[[#This Row],[BookingDate]],"mmm-yyy") -> Jan-2024 | AA23: =IF(Table1[[#This Row],[ResolutionHours]]="","Pending",IF(Table1[[#This Row],[ResolutionHours]]<=4,"0-4 Hours",IF(Table1[[#This Row],[ResolutionHours]]<=8,"5-8 Hours",IF(Table1[[#This Row],[ResolutionHours]]<=24,"9-24 Hours",IF(Table1[[#This Row],[ResolutionHours]]<=48,"25-48 Hours","48+ Hours"))))) -> 0-4 Hours | AB23: =IF(Table1[[#This Row],[ResolutionHours]]="","",Table1[[#This Row],[ResolutionHours]]-Table1[[#This Row],[SLATargetHours]]) -> -0.4
A24: INM-0575 | B24: INM | C24: 45297.172 | D24: P3 | E24: Application Down | F24: Reporting | G24: INM ticket requiring operational handling | H24: Closed | I24: Infrastructure Team | J24: Manoj | K24: 24 | L24: 3.45 | M24: 9.61 | N24: 45297.573 | O24: Met | P24: 9.61 | Q24: Medium | R24: UK | S24: Monitoring Alert | T24: Configuration Error | U24: No | V24: No | W24: Met | X24: =YEAR(Table1[[#This Row],[BookingDate]]) -> 2024 | Y24: =TEXT(Table1[[#This Row],[BookingDate]],"mmm") -> Jan | Z24: =TEXT(Table1[[#This Row],[BookingDate]],"mmm-yyy") -> Jan-2024 | AA24: =IF(Table1[[#This Row],[ResolutionHours]]="","Pending",IF(Table1[[#This Row],[ResolutionHours]]<=4,"0-4 Hours",IF(Table1[[#This Row],[ResolutionHours]]<=8,"5-8 Hours",IF(Table1[[#This Row],[ResolutionHours]]<=24,"9-24 Hours",IF(Table1[[#This Row],[ResolutionHours]]<=48,"25-48 Hours","48+ Hours"))))) -> 9-24 Hours | AB24: =IF(Table1[[#This Row],[ResolutionHours]]="","",Table1[[#This Row],[ResolutionHours]]-Table1[[#This Row],[SLATargetHours]]) -> -14.39
A25: SRM-0345 | B25: SRM | C25: 45297.275 | D25: P4 | E25: New User Setup | F25: Infrastructure | G25: SRM ticket requiring operational handling | H25: Answered | I25: Security Team | J25: Arjun | K25: 48 | L25: 6.19 | M25: 21.93 | N25: 45298.189 | O25: Met | P25: 21.93 | Q25: Medium | R25: Europe | S25: Email | T25: Infrastructure Failure | U25: No | V25: No | W25: Met | X25: =YEAR(Table1[[#This Row],[BookingDate]]) -> 2024 | Y25: =TEXT(Table1[[#This Row],[BookingDate]],"mmm") -> Jan | Z25: =TEXT(Table1[[#This Row],[BookingDate]],"mmm-yyy") -> Jan-2024 | AA25: =IF(Table1[[#This Row],[ResolutionHours]]="","Pending",IF(Table1[[#This Row],[ResolutionHours]]<=4,"0-4 Hours",IF(Table1[[#This Row],[ResolutionHours]]<=8,"5-8 Hours",IF(Table1[[#This Row],[ResolutionHours]]<=24,"9-24 Hours",IF(Table1[[#This Row],[ResolutionHours]]<=48,"25-48 Hours","48+ Hours"))))) -> 9-24 Hours | AB25: =IF(Table1[[#This Row],[ResolutionHours]]="","",Table1[[#This Row],[ResolutionHours]]-Table1[[#This Row],[SLATargetHours]]) -> -26.07
A26: INM-0104 | B26: INM | C26: 45297.382 | D26: P4 | E26: Database Issue | F26: Access | G26: INM ticket requiring operational handling | H26: Closed | I26: App Support | J26: Rahul | K26: 48 | L26: 3.98 | M26: 43.12 | N26: 45299.178 | O26: Met | P26: 43.12 | Q26: Medium | R26: APAC | S26: Portal | T26: Configuration Error | U26: No | V26: No | W26: Met | X26: =YEAR(Table1[[#This Row],[BookingDate]]) -> 2024 | Y26: =TEXT(Table1[[#This Row],[BookingDate]],"mmm") -> Jan | Z26: =TEXT(Table1[[#This Row],[BookingDate]],"mmm-yyy") -> Jan-2024 | AA26: =IF(Table1[[#This Row],[ResolutionHours]]="","Pending",IF(Table1[[#This Row],[ResolutionHours]]<=4,"0-4 Hours",IF(Table1[[#This Row],[ResolutionHours]]<=8,"5-8 Hours",IF(Table1[[#This Row],[ResolutionHours]]<=24,"9-24 Hours",IF(Table1[[#This Row],[ResolutionHours]]<=48,"25-48 Hours","48+ Hours"))))) -> 25-48 Hours | AB26: =IF(Table1[[#This Row],[ResolutionHours]]="","",Table1[[#This Row],[ResolutionHours]]-Table1[[#This Row],[SLATargetHours]]) -> -4.88
A27: SRM-0999 | B27: SRM | C27: 45297.553 | D27: P3 | E27: Software Installation | F27: Infrastructure | G27: SRM ticket requiring operational handling | H27: Closed | I27: App Support | J27: Swati | K27: 24 | L27: 2.4 | M27: 12.1 | N27: 45298.058 | O27: Met | P27: 12.1 | Q27: Low | R27: US | S27: Phone | T27: Application Defect | U27: No | V27: No | W27: Met | X27: =YEAR(Table1[[#This Row],[BookingDate]]) -> 2024 | Y27: =TEXT(Table1[[#This Row],[BookingDate]],"mmm") -> Jan | Z27: =TEXT(Table1[[#This Row],[BookingDate]],"mmm-yyy") -> Jan-2024 | AA27: =IF(Table1[[#This Row],[ResolutionHours]]="","Pending",IF(Table1[[#This Row],[ResolutionHours]]<=4,"0-4 Hours",IF(Table1[[#This Row],[ResolutionHours]]<=8,"5-8 Hours",IF(Table1[[#This Row],[ResolutionHours]]<=24,"9-24 Hours",IF(Table1[[#This Row],[ResolutionHours]]<=48,"25-48 Hours","48+ Hours"))))) -> 9-24 Hours | AB27: =IF(Table1[[#This Row],[ResolutionHours]]="","",Table1[[#This Row],[ResolutionHours]]-Table1[[#This Row],[SLATargetHours]]) -> -11.9
A28: INM-0707 | B28: INM | C28: 45297.741 | D28: P2 | E28: Login/Access | F28: Security | G28: INM ticket requiring operational handling | H28: Assigned | I28: App Support | J28: Pooja | K28: 8 | L28: 0.69 | O28: Pending | P28: 17382.22 | Q28: High | R28: US | S28: Service Desk | T28: Network Issue | U28: No | V28: No | W28: Pending | X28: =YEAR(Table1[[#This Row],[BookingDate]]) -> 2024 | Y28: =TEXT(Table1[[#This Row],[BookingDate]],"mmm") -> Jan | Z28: =TEXT(Table1[[#This Row],[BookingDate]],"mmm-yyy") -> Jan-2024 | AA28: =IF(Table1[[#This Row],[ResolutionHours]]="","Pending",IF(Table1[[#This Row],[ResolutionHours]]<=4,"0-4 Hours",IF(Table1[[#This Row],[ResolutionHours]]<=8,"5-8 Hours",IF(Table1[[#This Row],[ResolutionHours]]<=24,"9-24 Hours",IF(Table1[[#This Row],[ResolutionHours]]<=48,"25-48 Hours","48+ Hours"))))) -> Pending | AB28: =IF(Table1[[#This Row],[ResolutionHours]]="","",Table1[[#This Row],[ResolutionHours]]-Table1[[#This Row],[SLATargetHours]])
A29: SRM-0569 | B29: SRM | C29: 45298.801 | D29: P4 | E29: Certificate Request | F29: Middleware | G29: SRM ticket requiring operational handling | H29: Assigned | I29: Middleware Team | J29: Manoj | K29: 48 | L29: 0.85 | O29: Pending | P29: 17356.78 | Q29: High | R29: Europe | S29: Email | T29: Unknown | U29: No | V29: No | W29: Pending | X29: =YEAR(Table1[[#This Row],[BookingDate]]) -> 2024 | Y29: =TEXT(Table1[[#This Row],[BookingDate]],"mmm") -> Jan | Z29: =TEXT(Table1[[#This Row],[BookingDate]],"mmm-yyy") -> Jan-2024 | AA29: =IF(Table1[[#This Row],[ResolutionHours]]="","Pending",IF(Table1[[#This Row],[ResolutionHours]]<=4,"0-4 Hours",IF(Table1[[#This Row],[ResolutionHours]]<=8,"5-8 Hours",IF(Table1[[#This Row],[ResolutionHours]]<=24,"9-24 Hours",IF(Table1[[#This Row],[ResolutionHours]]<=48,"25-48 Hours","48+ Hours"))))) -> Pending | AB29: =IF(Table1[[#This Row],[ResolutionHours]]="","",Table1[[#This Row],[ResolutionHours]]-Table1[[#This Row],[SLATargetHours]])
A30: PRM-0204 | B30: PRM | C30: 45298.961 | D30: P1 | E30: Database Root Cause | F30: Security | G30: PRM ticket requiring operational handling | H30: Closed | I30: App Support | J30: Meera | K30: 4 | L30: 0.9 | M30: 2.22 | N30: 45299.054 | O30: Met | P30: 2.22 | Q30: Critical | R30: UK | S30: Phone | T30: Infrastructure Failure | U30: No | V30: Yes | W30: Met | X30: =YEAR(Table1[[#This Row],[BookingDate]]) -> 2024 | Y30: =TEXT(Table1[[#This Row],[BookingDate]],"mmm") -> Jan | Z30: =TEXT(Table1[[#This Row],[BookingDate]],"mmm-yyy") -> Jan-2024 | AA30: =IF(Table1[[#This Row],[ResolutionHours]]="","Pending",IF(Table1[[#This Row],[ResolutionHours]]<=4,"0-4 Hours",IF(Table1[[#This Row],[ResolutionHours]]<=8,"5-8 Hours",IF(Table1[[#This Row],[ResolutionHours]]<=24,"9-24 Hours",IF(Table1[[#This Row],[ResolutionHours]]<=48,"25-48 Hours","48+ Hours"))))) -> 0-4 Hours | AB30: =IF(Table1[[#This Row],[ResolutionHours]]="","",Table1[[#This Row],[ResolutionHours]]-Table1[[#This Row],[SLATargetHours]]) -> -1.78
A31: INM-0303 | B31: INM | C31: 45299.249 | D31: P3 | E31: Performance Issue | F31: Security | G31: INM ticket requiring operational handling | H31: Closed | I31: Middleware Team | J31: Kiran | K31: 24 | L31: 0.13 | M31: 18.07 | N31: 45300.002 | O31: Met | P31: 18.07 | Q31: High | R31: UK | S31: Email | T31: Third-Party Dependency | U31: No | V31: No | W31: Met | X31: =YEAR(Table1[[#This Row],[BookingDate]]) -> 2024 | Y31: =TEXT(Table1[[#This Row],[BookingDate]],"mmm") -> Jan | Z31: =TEXT(Table1[[#This Row],[BookingDate]],"mmm-yyy") -> Jan-2024 | AA31: =IF(Table1[[#This Row],[ResolutionHours]]="","Pending",IF(Table1[[#This Row],[ResolutionHours]]<=4,"0-4 Hours",IF(Table1[[#This Row],[ResolutionHours]]<=8,"5-8 Hours",IF(Table1[[#This Row],[ResolutionHours]]<=24,"9-24 Hours",IF(Table1[[#This Row],[ResolutionHours]]<=48,"25-48 Hours","48+ Hours"))))) -> 9-24 Hours | AB31: =IF(Table1[[#This Row],[ResolutionHours]]="","",Table1[[#This Row],[ResolutionHours]]-Table1[[#This Row],[SLATargetHours]]) -> -5.93
A32: SRM-0915 | B32: SRM | C32: 45299.378 | D32: P4 | E32: Access Request | F32: Security | G32: SRM ticket requiring operational handling | H32: Assigned | I32: Infrastructure Team | J32: Anil | K32: 48 | L32: 1.09 | O32: Pending | P32: 17342.93 | Q32: Low | R32: India | S32: Phone | T32: Infrastructure Failure | U32: No | V32: No | W32: Pending | X32: =YEAR(Table1[[#This Row],[BookingDate]]) -> 2024 | Y32: =TEXT(Table1[[#This Row],[BookingDate]],"mmm") -> Jan | Z32: =TEXT(Table1[[#This Row],[BookingDate]],"mmm-yyy") -> Jan-2024 | AA32: =IF(Table1[[#This Row],[ResolutionHours]]="","Pending",IF(Table1[[#This Row],[ResolutionHours]]<=4,"0-4 Hours",IF(Table1[[#This Row],[ResolutionHours]]<=8,"5-8 Hours",IF(Table1[[#This Row],[ResolutionHours]]<=24,"9-24 Hours",IF(Table1[[#This Row],[ResolutionHours]]<=48,"25-48 Hours","48+ Hours"))))) -> Pending | AB32: =IF(Table1[[#This Row],[ResolutionHours]]="","",Table1[[#This Row],[ResolutionHours]]-Table1[[#This Row],[SLATargetHours]])
A33: SRM-0749 | B33: SRM | C33: 45299.943 | D33: P3 | E33: Account Request | F33: Security | G33: SRM ticket requiring operational handling | H33: Assigned | I33: App Support | J33: Pooja | K33: 24 | L33: 0.7 | O33: Pending | P33: 17329.38 | Q33: High | R33: APAC | S33: Monitoring Alert | T33: Unknown | U33: No | V33: No | W33: Pending | X33: =YEAR(Table1[[#This Row],[BookingDate]]) -> 2024 | Y33: =TEXT(Table1[[#This Row],[BookingDate]],"mmm") -> Jan | Z33: =TEXT(Table1[[#This Row],[BookingDate]],"mmm-yyy") -> Jan-2024 | AA33: =IF(Table1[[#This Row],[ResolutionHours]]="","Pending",IF(Table1[[#This Row],[ResolutionHours]]<=4,"0-4 Hours",IF(Table1[[#This Row],[ResolutionHours]]<=8,"5-8 Hours",IF(Table1[[#This Row],[ResolutionHours]]<=24,"9-24 Hours",IF(Table1[[#This Row],[ResolutionHours]]<=48,"25-48 Hours","48+ Hours"))))) -> Pending | AB33: =IF(Table1[[#This Row],[ResolutionHours]]="","",Table1[[#This Row],[ResolutionHours]]-Table1[[#This Row],[SLATargetHours]])
A34: INM-0801 | B34: INM | C34: 45300.839 | D34: P4 | E34: Login/Access | F34: Infrastructure | G34: INM ticket requiring operational handling | H34: Closed | I34: Security Team | J34: Rohit | K34: 48 | L34: 0.82 | M34: 13.9 | N34: 45301.418 | O34: Met | P34: 13.9 | Q34: High | R34: India | S34: Monitoring Alert | T34: Application Defect | U34: No | V34: No | W34: Met | X34: =YEAR(Table1[[#This Row],[BookingDate]]) -> 2024 | Y34: =TEXT(Table1[[#This Row],[BookingDate]],"mmm") -> Jan | Z34: =TEXT(Table1[[#This Row],[BookingDate]],"mmm-yyy") -> Jan-2024 | AA34: =IF(Table1[[#This Row],[ResolutionHours]]="","Pending",IF(Table1[[#This Row],[ResolutionHours]]<=4,"0-4 Hours",IF(Table1[[#This Row],[ResolutionHours]]<=8,"5-8 Hours",IF(Table1[[#This Row],[ResolutionHours]]<=24,"9-24 Hours",IF(Table1[[#This Row],[ResolutionHours]]<=48,"25-48 Hours","48+ Hours"))))) -> 9-24 Hours | AB34: =IF(Table1[[#This Row],[ResolutionHours]]="","",Table1[[#This Row],[ResolutionHours]]-Table1[[#This Row],[SLATargetHours]]) -> -34.1
A35: INM-0790 | B35: INM | C35: 45300.993 | D35: P2 | E35: Integration Failure | F35: Application | G35: INM ticket requiring operational handling | H35: In Process | I35: Database Team | J35: Vikram | K35: 8 | L35: 0.57 | O35: Pending | P35: 17304.16 | Q35: High | R35: UK | S35: Service Desk | T35: Unknown | U35: No | V35: No | W35: Pending | X35: =YEAR(Table1[[#This Row],[BookingDate]]) -> 2024 | Y35: =TEXT(Table1[[#This Row],[BookingDate]],"mmm") -> Jan | Z35: =TEXT(Table1[[#This Row],[BookingDate]],"mmm-yyy") -> Jan-2024 | AA35: =IF(Table1[[#This Row],[ResolutionHours]]="","Pending",IF(Table1[[#This Row],[ResolutionHours]]<=4,"0-4 Hours",IF(Table1[[#This Row],[ResolutionHours]]<=8,"5-8 Hours",IF(Table1[[#This Row],[ResolutionHours]]<=24,"9-24 Hours",IF(Table1[[#This Row],[ResolutionHours]]<=48,"25-48 Hours","48+ Hours"))))) -> Pending | AB35: =IF(Table1[[#This Row],[ResolutionHours]]="","",Table1[[#This Row],[ResolutionHours]]-Table1[[#This Row],[SLATargetHours]])
A36: SRM-0537 | B36: SRM | C36: 45301.494 | D36: P5 | E36: Access Request | F36: Security | G36: SRM ticket requiring operational handling | H36: In Process | I36: Middleware Team | J36: Sneha | K36: 72 | L36: 11.2 | O36: Pending | P36: 17292.16 | Q36: Low | R36: UK | S36: Email | T36: Application Defect | U36: No | V36: No | W36: Pending | X36: =YEAR(Table1[[#This Row],[BookingDate]]) -> 2024 | Y36: =TEXT(Table1[[#This Row],[BookingDate]],"mmm") -> Jan | Z36: =TEXT(Table1[[#This Row],[BookingDate]],"mmm-yyy") -> Jan-2024 | AA36: =IF(Table1[[#This Row],[ResolutionHours]]="","Pending",IF(Table1[[#This Row],[ResolutionHours]]<=4,"0-4 Hours",IF(Table1[[#This Row],[ResolutionHours]]<=8,"5-8 Hours",IF(Table1[[#This Row],[ResolutionHours]]<=24,"9-24 Hours",IF(Table1[[#This Row],[ResolutionHours]]<=48,"25-48 Hours","48+ Hours"))))) -> Pending | AB36: =IF(Table1[[#This Row],[ResolutionHours]]="","",Table1[[#This Row],[ResolutionHours]]-Table1[[#This Row],[SLATargetHours]])
A37: PRM-0733 | B37: PRM | C37: 45301.762 | D37: P4 | E37: Security Vulnerability | F37: Reporting | G37: PRM ticket requiring operational handling | H37: Closed | I37: Middleware Team | J37: Amit | K37: 48 | L37: 1.99 | M37: 20.92 | N37: 45302.633 | O37: Met | P37: 20.92 | Q37: High | R37: Europe | S37: Phone | T37: Third-Party Dependency | U37: No | V37: No | W37: Met | X37: =YEAR(Table1[[#This Row],[BookingDate]]) -> 2024 | Y37: =TEXT(Table1[[#This Row],[BookingDate]],"mmm") -> Jan | Z37: =TEXT(Table1[[#This Row],[BookingDate]],"mmm-yyy") -> Jan-2024 | AA37: =IF(Table1[[#This Row],[ResolutionHours]]="","Pending",IF(Table1[[#This Row],[ResolutionHours]]<=4,"0-4 Hours",IF(Table1[[#This Row],[ResolutionHours]]<=8,"5-8 Hours",IF(Table1[[#This Row],[ResolutionHours]]<=24,"9-24 Hours",IF(Table1[[#This Row],[ResolutionHours]]<=48,"25-48 Hours","48+ Hours"))))) -> 9-24 Hours | AB37: =IF(Table1[[#This Row],[ResolutionHours]]="","",Table1[[#This Row],[ResolutionHours]]-Table1[[#This Row],[SLATargetHours]]) -> -27.08
A38: INM-0410 | B38: INM | C38: 45302.187 | D38: P2 | E38: Database Issue | F38: Security | G38: INM ticket requiring operational handling | H38: Closed | I38: App Support | J38: Ravi | K38: 8 | L38: 1.52 | M38: 5.14 | N38: 45302.402 | O38: Met | P38: 5.14 | Q38: High | R38: India | S38: Monitoring Alert | T38: Application Defect | U38: No | V38: Yes | W38: Met | X38: =YEAR(Table1[[#This Row],[BookingDate]]) -> 2024 | Y38: =TEXT(Table1[[#This Row],[BookingDate]],"mmm") -> Jan | Z38: =TEXT(Table1[[#This Row],[BookingDate]],"mmm-yyy") -> Jan-2024 | AA38: =IF(Table1[[#This Row],[ResolutionHours]]="","Pending",IF(Table1[[#This Row],[ResolutionHours]]<=4,"0-4 Hours",IF(Table1[[#This Row],[ResolutionHours]]<=8,"5-8 Hours",IF(Table1[[#This Row],[ResolutionHours]]<=24,"9-24 Hours",IF(Table1[[#This Row],[ResolutionHours]]<=48,"25-48 Hours","48+ Hours"))))) -> 5-8 Hours | AB38: =IF(Table1[[#This Row],[ResolutionHours]]="","",Table1[[#This Row],[ResolutionHours]]-Table1[[#This Row],[SLATargetHours]]) -> -2.86
A39: PRM-0111 | B39: PRM | C39: 45302.308 | D39: P3 | E39: Process Gap | F39: Application | G39: PRM ticket requiring operational handling | H39: Closed | I39: Security Team | J39: Kavya | K39: 24 | L39: 1.73 | M39: 19.51 | N39: 45303.12 | O39: Met | P39: 19.51 | Q39: Medium | R39: Europe | S39: Service Desk | T39: Infrastructure Failure | U39: No | V39: No | W39: Met | X39: =YEAR(Table1[[#This Row],[BookingDate]]) -> 2024 | Y39: =TEXT(Table1[[#This Row],[BookingDate]],"mmm") -> Jan | Z39: =TEXT(Table1[[#This Row],[BookingDate]],"mmm-yyy") -> Jan-2024 | AA39: =IF(Table1[[#This Row],[ResolutionHours]]="","Pending",IF(Table1[[#This Row],[ResolutionHours]]<=4,"0-4 Hours",IF(Table1[[#This Row],[ResolutionHours]]<=8,"5-8 Hours",IF(Table1[[#This Row],[ResolutionHours]]<=24,"9-24 Hours",IF(Table1[[#This Row],[ResolutionHours]]<=48,"25-48 Hours","48+ Hours"))))) -> 9-24 Hours | AB39: =IF(Table1[[#This Row],[ResolutionHours]]="","",Table1[[#This Row],[ResolutionHours]]-Table1[[#This Row],[SLATargetHours]]) -> -4.49
A40: SRM-0063 | B40: SRM | C40: 45302.314 | D40: P2 | E40: Configuration Change | F40: Middleware | G40: SRM ticket requiring operational handling | H40: Closed | I40: Service Desk | J40: Meera | K40: 8 | L40: 0.18 | M40: 3.71 | N40: 45302.469 | O40: Met | P40: 3.71 | Q40: High | R40: India | S40: Portal | T40: Capacity Constraint | U40: No | V40: No | W40: Met | X40: =YEAR(Table1[[#This Row],[BookingDate]]) -> 2024 | Y40: =TEXT(Table1[[#This Row],[BookingDate]],"mmm") -> Jan | Z40: =TEXT(Table1[[#This Row],[BookingDate]],"mmm-yyy") -> Jan-2024 | AA40: =IF(Table1[[#This Row],[ResolutionHours]]="","Pending",IF(Table1[[#This Row],[ResolutionHours]]<=4,"0-4 Hours",IF(Table1[[#This Row],[ResolutionHours]]<=8,"5-8 Hours",IF(Table1[[#This Row],[ResolutionHours]]<=24,"9-24 Hours",IF(Table1[[#This Row],[ResolutionHours]]<=48,"25-48 Hours","48+ Hours"))))) -> 0-4 Hours | AB40: =IF(Table1[[#This Row],[ResolutionHours]]="","",Table1[[#This Row],[ResolutionHours]]-Table1[[#This Row],[SLATargetHours]]) -> -4.29
...

Sheet Operation Tickets data Analysis
A1: Total Tickets | C1: Volume by Ticket Type | F1: Volume by Ticket Prority | I1: Volume by Sub-Category | L1: Volume by Team
A3: Count of TicketID | C3: Row Labels | D3: Count of TicketID | F3: Row Labels | G3: Count of TicketID | I3: Row Labels | J3: Count of TicketID | L3: Row Labels | M3: Count of TicketID
A4: 1511 | C4: INM | D4: 492 | F4: P1 | G4: 67 | I4: Database | J4: 191 | L4: Service Desk | M4: 476
C5: PRM | D5: 505 | F5: P2 | G5: 151 | I5: Security | J5: 205 | L5: Middleware Team | M5: 486
C6: SRM | D6: 514 | F6: P3 | G6: 400 | I6: Application | J6: 209 | L6: Database Team | M6: 497
C7: Grand Total | D7: 1511 | F7: P4 | G7: 572 | I7: Infrastructure | J7: 210 | L7: Infrastructure Team | M7: 510
F8: P5 | G8: 321 | I8: Middleware | J8: 215 | L8: App Support | M8: 513
F9: Grand Total | G9: 1511 | I9: Access | J9: 227 | L9: Security Team | M9: 518
I10: Reporting | J10: 254 | L10: Grand Total | M10: 3000
I11: Grand Total | J11: 1511
A14: Volume by Ticket Status | D14: Volume by SLA Status
A16: Row Labels | B16: Count of TicketID | D16: Row Labels | E16: Count of TicketID | G16: KPI | H16: Value | J16: SLA Performance by Priority
A17: Answered | B17: 138 | D17: Breached | E17: 138 | G17: Total Tickets | H17: =COUNTA(All_Tickets!A:A)-1 -> 3000
A18: Assigned | B18: 151 | D18: Met | E18: 750 | G18: Closed Tickets | H18: =COUNTIF(All_Tickets!H:H,"Closed") -> 1511 | J18: Count of TicketID | K18: Column Labels
A19: Closed | B19: 750 | D19: Pending | E19: 623 | G19: Active Tickets | H19: =COUNTIF(All_Tickets!H:H,"Assigned")+COUNTIF(All_Tickets!H:H,"In Process")+COUNTIF(All_Tickets!H:H,"Noticed") -> 1230 | J19: Row Labels | K19: Breached | L19: Met | M19: Pending | N19: Grand Total
A20: In Process | B20: 331 | D20: Grand Total | E20: 1511 | G20: Answered Tickets | H20: =COUNTIF(All_Tickets!H:H,"Answered") -> 259 | J20: P1 | K20: 8 | L20: 34 | M20: 25 | N20: 67
A21: Noticed | B21: 141 | G21: SLA Compliance % | H21: =COUNTIF(All_Tickets!W:W,"Met")/(COUNTIF(All_Tickets!W:W,"Met")+COUNTIF(All_Tickets!W:W,"Breached")) -> 0.83728814 | J21: P2 | K21: 13 | L21: 72 | M21: 66 | N21: 151
A22: Grand Total | B22: 1511 | G22: SLA Breaches | H22: =COUNTIF(All_Tickets!W:W,"Breached") -> 288 | J22: P3 | K22: 41 | L22: 196 | M22: 163 | N22: 400
G23: SLA Pending | H23: =COUNTIF(All_Tickets!W:W,"Pending") -> 1230 | J23: P4 | K23: 52 | L23: 299 | M23: 221 | N23: 572
G24: Average Resolution Hours | H24: =AVERAGE(All_Tickets!M:M) -> 30.007294 | J24: P5 | K24: 24 | L24: 149 | M24: 148 | N24: 321
G25: Escalated Tickets | H25: =COUNTIF(All_Tickets!V:V,"Yes") -> 317 | J25: Grand Total | K25: 138 | L25: 750 | M25: 623 | N25: 1511
G26: Reopened Tickets | H26: =COUNTIF(All_Tickets!U:U,"Yes") -> 138
A27: Average Resolution time by Team | G27: SLA Met | H27: =COUNTIF(All_Tickets!W:W,"Met") -> 1482
A28: Row Labels | B28: Average of ResolutionHours | D28: Monthly Trend
A29: App Support | B29: 27.323377 | D29: Row Labels | E29: Count of TicketID
A30: Database Team | B30: 32.065928 | D30: Apr-2024 | E30: 157 | G30: Average Resolution time by Priority
A31: Infrastructure Team | B31: 32.616316 | D31: Mar-2024 | E31: 142 | G31: Row Labels | H31: Average of ResolutionHours
A32: Middleware Team | B32: 28.690355 | D32: Aug-2024 | E32: 133 | G32: P1 | H32: 2.965
A33: Security Team | B33: 29.949034 | D33: Nov-2024 | E33: 133 | G33: P2 | H33: 5.688
A34: Service Desk | B34: 26.742558 | D34: May-2024 | E34: 129 | G34: P3 | H34: 18.860506
A35: Grand Total | B35: 29.682691 | D35: Jul-2024 | E35: 129 | G35: P4 | H35: 34.896581
D36: Dec-2024 | E36: 124 | G36: P5 | H36: 52.205665
D37: Jun-2024 | E37: 123 | G37: Grand Total | H37: 29.682691
D38: Oct-2024 | E38: 121
A39: Resolution Bucket Analysis | D39: Jan-2024 | E39: 118
A40: Row Labels | B40: Count of TicketID | D40: Sep-2024 | E40: 104 | G40: Escalated Tickets | J40: Reopened Tickets
A41: 0-4 Hours | B41: 81 | D41: Feb-2024 | E41: 98 | G41: Row Labels | H41: Count of TicketID | J41: Row Labels | K41: Count of TicketID
A42: 5-8 Hours | B42: 83 | D42: Grand Total | E42: 1511 | G42: No | H42: 1341 | J42: No | K42: 1442
A43: 48+ Hours | B43: 138 | G43: Yes | H43: 170 | J43: Yes | K43: 69
A44: 25-48 Hours | B44: 243 | G44: Grand Total | H44: 1511 | J44: Grand Total | K44: 1511
...

Sheet Operations Dashboard
B1: ITSM INCIDENT ANALYSIS DASHBOARD
I3: Operational Performance | K3: SLA | M3: WorkLoad | N3: Resolution Analysis | O3: 2024-2025
B5: Total Tickets | E5: Closed Tickets | H5: Active Tickets | K5: SLA Compliance | N5: SLA Breaches | Q5: Avg Resolution Hours
B6: ='Operation Tickets data Analysis'!H17 -> 3000 | E6: ='Operation Tickets data Analysis'!H18 -> 1511 | H6: ='Operation Tickets data Analysis'!H19 -> 1230 | K6: ='Operation Tickets data Analysis'!H21 -> 0.83728814 | N6: ='Operation Tickets data Analysis'!H22 -> 288 | Q6: ='Operation Tickets data Analysis'!H24 -> 30.007294
